Traceback (most recent call last):
  File "main.py", line 56, in <module>
    for i, data in enumerate(dataloader, 0):
  File "/home/mvries/.conda/envs/dcfn/lib/python3.7/site-packages/torch/utils/data/dataloader.py", line 435, in __next__
    data = self._next_data()
  File "/home/mvries/.conda/envs/dcfn/lib/python3.7/site-packages/torch/utils/data/dataloader.py", line 475, in _next_data
    data = self._dataset_fetcher.fetch(index)  # may raise StopIteration
  File "/home/mvries/.conda/envs/dcfn/lib/python3.7/site-packages/torch/utils/data/_utils/fetch.py", line 44, in fetch
    data = [self.dataset[idx] for idx in possibly_batched_index]
  File "/home/mvries/.conda/envs/dcfn/lib/python3.7/site-packages/torch/utils/data/_utils/fetch.py", line 44, in <listcomp>
    data = [self.dataset[idx] for idx in possibly_batched_index]
  File "/home/mvries/FoldingNetNew/dataset.py", line 40, in __getitem__
    image = PyntCloud.from_file(img_path + '.ply')
  File "/home/mvries/.conda/envs/dcfn/lib/python3.7/site-packages/pyntcloud/core_class.py", line 130, in from_file
    return cls(**FROM_FILE[ext](filename, **kwargs))
  File "/home/mvries/.conda/envs/dcfn/lib/python3.7/site-packages/pyntcloud/io/ply.py", line 46, in read_ply
    with open(filename, 'rb') as ply:
FileNotFoundError: [Errno 2] No such file or directory: '/data/scratch/DBI/DUDBI/DYNCESYS/mvries/Datasets/Single_cell_Treat_PointCloud/Palbociclib/0001_0001_accelerator_20210318_bakal03_erk_main_21-03-18_17-38-12.ply'
